Workbook
Name ref_6_3066550: 其他统计!$A$2
Name ref_7_3066550: 其他统计!$A$4

Sheet 支出
A1: 日期 | B1: 星期 | C1: 日合计 | D1: 类型 | E1: DETAIL | F1: 支出 | H1: 支出财报总览
A2: 9月 | C2: =SUM(F3:F112) -> 2798.73 | H2: 最终财报信息归入东阁
A3: 45171 | B3: SA | C3: =SUM(F3:F15) -> 553.84 | D3: 交通 | E3: 哈喽出行 | F3: 4.89
D4: 交通 | E4: 哈喽出行 | F4: 2.68 | H4: 类型 | I4: 求和项:支出
D5: 学习 | E5: 拼多多高级笔记本 | F5: 27.68 | H5: 餐费 | I5: 664
D6: 学习 | E6: 拼多多一般笔记本 | F6: 10.93 | H6: 交通 | I6: 42.07 | J6: 月份 | K6: 金额
D7: 学习 | E7: 拼多多笔芯0.5 | F7: 32 | H7: 生活 | I7: 1008.12 | J7: 9 | K7: 2798.73
D8: 学习 | E8: 拼多多笔芯按动 | F8: 19.9 | H8: 投资 | I8: 520.79 | J8: 10 | K8: 1771.24
D9: 生活 | E9: 拼多多日光灯 | F9: 19.76 | H9: 外务 | I9: 32.54 | J9: 11 | K9: 1532.44
D10: 生活 | E10: 插排 | F10: 39 | H10: 学习 | I10: 531.21 | J10: 12 | K10: 1753.07
D11: 生活 | E11: 锁头x2 | F11: 10 | H11: (空白)
D12: 生活 | E12: 军训服装 | F12: 135 | H12: 总支出 | I12: =SUM(I5:I10) -> 2798.73
D13: 生活 | E13: 沐浴水费押金 | F13: 30
D14: 餐费 | E14: 晚饭 | F14: 12
D15: 生活 | E15: 网络 开户60+150半年 | F15: 210
A16: 45172 | B16: SU | C16: =SUM(F16:F22) -> 153.25 | D16: 餐费 | E16: 早饭 3+4 | F16: 7
D17: 交通 | E17: 哈喽包月 | F17: 10.5
D18: 餐费 | E18: 午饭 | F18: 12
D19: 生活 | E19: 路由器 合资四人 | F19: 24.75
D20: 餐费 | E20: 晚饭 | F20: 12
D21: 生活 | E21: 网线 | F21: 11.5
D22: 生活 | E22: 梯子 合资双人151 | F22: 75.5
A23: 45173 | B23: MO | C23: =F23+F24+F25+F27+F28+F29+F30 -> 198.25 | D23: 餐费 | E23: 早餐 | F23: 4
D24: 投资 | E24: 九月投资支出30+先前业务支出40+15 | F24: 85
D25: 生活 | E25: 一卡移动话费 | F25: 20
D26: 投资 | E26: 8月投资支出100+40+30=170 | F26: 0
D27: 餐费 | E27: 午餐 | F27: 15
D28: 生活 | E28: DD订水四人合资 | F28: 2.25
D29: 生活 | E29: DD订水60押金 | F29: 60
D30: 餐费 | E30: 晚餐 | F30: 12 | H30: 九月
A31: 45174 | B31: TU | C31: =SUM(F31:F35) -> 67.44 | D31: 餐费 | E31: 早餐 | F31: 4
D32: 餐费 | E32: 午餐 | F32: 12
D33: 餐费 | E33: 晚餐 | F33: 12
D34: 生活 | E34: 明天早餐双人合资13.6元 | F34: 6.9
D35: 外务 | E35: 弟学习用书 | F35: 32.54
D36: 投资 | E36: 9.4日投资快递延迟补贴 未取 | F36: 0
A37: 45175 | B37: WE | C37: =SUM(F38:F39) -> 261 | D37: 生活 | E37: 陈权合资水费2.25未交 | F37: 0
D38: 生活 | E38: 校服 | F38: 233
D39: 餐费 | E39: 餐费 | F39: 28
A40: 45176 | B40: TH | C40: =SUM(F40:F42) -> 70.25 | D40: 餐费 | E40: 餐费 | F40: 28
...

Sheet 收入
A1: 日期 | B1: 星期 | C1: DETAIL | D1: EARNING
A2: 9月
A3: 45171 | B3: SA | C3: MA | D3: 500
C4: 八月办卡 | D4: 270
A5: 45178 | B5: SA | C5: 二手书再卖10+5+10 | D5: 25
A6: 45179 | B6: SU | C6: 二手书再卖 | D6: 16
C7: 二手书再卖 | D7: 8
A8: 45184 | B8: FR | C8: 办卡业务 | D8: 100
A9: 45191 | B9: FR | C9: 办卡业务 | D9: 90
A10: 45197 | B10: TH | C10: BA | D10: 200
A11: 45198 | B11: FR | C11: 高中舍友群和组织部部门群 | D11: =3.08+1.67+0.21+0.54+0.88+1.23+0.14+1.25+0.35+0.75+2.65+4.99+3.23+0.1+0.21+1.35+0.7+0.15+0.62+1.12 -> 25.22
A12: 9月收入 | B12: 合计 | C12: =SUM(D3:D11) -> 1234.22 | D12: =D4+D5+D6+D7+D8+D9+D11 -> 534.22
A13: 10月
A14: 45200 | B14: MO | C14: 高中宿舍群 | D14: =0.5+1.47+0.64 -> 2.61
A15: 45205 | B15: FR | C15: MA | D15: 50
A16: 45218 | B16: TH | C16: 办卡业务 | D16: 100
A17: 45215 | B17: MO | C17: 广告红包 | D17: 0.03
A18: 45216 | B18: TU | C18: 广告红包 | D18: 0.01
A19: 45217 | B19: WE | C19: 广告红包 | D19: 0.01
A20: 45228 | B20: SU | C20: MA BA | D20: 400
A21: 10月收入 | B21: 合计 | C21: =SUM(D14:D20) -> 552.66 | D21: 20
A23: 12月
A24: 45263 | B24: SU | C24: BA | D24: 500

Sheet 8.9月办卡业务统计区
A1: 时间 | B1: 微信号 | C1: 运营商 | D1: 补贴详细 | E1: 净收入情况 | F1: 列1 | G1: 列2
A2: 45146 | B2: KDB17LD77 | C2: 联通 | D2: 40 | E2: 130 | I2: 前期自己号投入100实际生活确实需要
A3: 45147 | B3: SamJH- | C3: 移动 | D3: 30 | E3: 70
A4: 45170 | B4: xx13168823354 | C4: 联通 | D4: 40+15 | E4: =170-40-15 -> 115 | F4: -55
A5: 45173 | B5: rys0025 | C5: 移动 | D5: 30 | E5: 70
A6: 45176 | B6: ju1145784568 | C6: 联通 | D6: 40 | E6: 130 | F6: -40
A7: 45182 | B7: c1744922738 | C7: 移动 | D7: 0 | E7: 90
A8: 45210 | B8: 蔡老师推广 | C8: 移动 | D8: 80 | E8: 20

Sheet 其他统计
A1: 日期 | B1: 日常开销维持建议 | C1: 费用
A2: 9月
A3: 45173 | B3: 日常饮食 | C3: 4+12+12=28 28*30=840
A4: 45175 | B4: 桶装饮水 | C4: 9元三天30天90左右 22.5一人
A5: 45178 | B5: 教材 | C5: 380.15
A6: 9/2-9/9 | B6: 第一周合计 | C6: 1742.43
A7: 45173 | B7: 银行卡内 | C7: 6008.5
A8: 45173 | B8: 现金 | C8: 450.8
A9: 45179 | B9: 银行卡内 | C9: 5145.9
B10: 二手书买入总70元7+2 实用5本 高数四本无用 | C10: 70
B11: 二手书再卖 用部分免费领的书抵 | C11: 41
A12: 45180 | B12: 电费4.88-3.05 4.94-3.09 5.96-3.73日均3.05有一日达8.69-5.76 | C12: 日均3.5平摊0.875一日一人
B13: 每度n元
B14: 3.05/4.88 | C14: =3.05/4.88 -> 0.625
B15: 3.18/5.08 | C15: =3.18/5.08 -> 0.62598425
B16: 5.14/8.23 | C16: =5.14/8.23 -> 0.62454435
B17: 0.84/1.35 | C17: =0.84/1.35 -> 0.62222222
B18: 1.04/1.66 | C18: =1.04/1.66 -> 0.62650602
B19: 0.06/0.09 | C19: =0.06/0.09 -> 0.66666667
A20: 45182 | B20: 至9/13预计本月办卡业务纯利润415元 | C20: 415
A21: 45184 | B21: 目前卡内 | C21: 4913.89
B22: 卡支出 | C22: 1468.11
A23: 45187 | B23: 目前卡内 | C23: 4493.89
B24: 卡支出 | C24: 1888.11
A25: 9/10-9/17 | B25: 第二周合计 | C25: 618.08
A26: 9/2-9/17 | B26: 开学两周总支出 | C26: 2387.01
A27: 45193 | B27: 军训结束时总支出 | C27: 2608.76
A28: 9/18-9/24 | B28: 第三周合计 | C28: 273.75
B29: 目前卡内 | C29: 4394.88
B30: 卡支出 | C30: 2078.11
A31: 9/25-9/30 | B31: 第四周总支出 | C31: 191
A32: 9/2-9/30 | B32: 月总支出 | C32: =C6+C25+C28+C31 -> 2825.26
A33: 9/2-9/30 | B33: 月总纳入 | C33: 1234.22
A34: 9/2-9/30 | B34: 月出库 | C34: =C32-C33 -> 1591.04
A41: 日期 | B41: 日常开销维持建议 | C41: 费用
A42: 10月
A43: 10/1-10/8 | B43: 第六周合计 | C43: 155.79
A44: 45213 | B44: 统计数据差距在红包的净支出折合结果
A45: 10/1-10/15 | B45: 八月银行卡总量15000 学费8988 | C45: =15000-8988 -> 6012
B46: 三个月平均 | C46: =6012/3 -> 2004
...
